Workbook
Name SegmentaciónDeDatos_Categoría: #N/A

Sheet Proveedores
A1: ID | B1: Nombre | C1: RUT | D1: Condición pago | E1: Contacto
A2: P01 | B2: Abrigos Los Andes | C2: 77.978.8769-7 | D2: Transferencia | E2: Abrigosfrios.cl
A3: P02 | B3: Blusas Sur de Chile | C3: 77.978.8769-8 | D3: Transferencia | E3: Blusasellas.cl
A4: P03 | B4: Pantalones elegantes SPA | C4: 78.7566.94785-9 | D4: Transferencia | E4: Confecciónmanual.cl
A5: P04 | B5: Flexi, SPA | C5: 67.9457.847-9 | D5: Transferencia | E5: Flexiechoes.cl
A6: P05 | B6: LEGITIMO | C6: 77.857.9867-6 | D6: Transferencia | E6: Legitimotrinidad.cl

Sheet Ordenes de Compra 
A1: OC 001 "ABRIGOS" | D1: OC 002 "BLUSAS"
A2: "Datos Comprador" | D2: "Datos Comprador"
A3: Empresa: | B3: Legacy SPA | D3: Empresa: | E3: Legacy SPA
A4: Rut: | B4: 77.756.968-8 | D4: Rut: | E4: 77.756.968-8
A5: Dirección: | B5: Av. Carlos Schorr, Talca | D5: Dirección: | E5: Av. Carlos Schorr, Talca
A6: Contacto: | B6: Legacy.cl | D6: Contacto: | E6: Legacy.cl
A7: Fecha: | B7: 46115 | D7: Fecha: | E7: 46115
A8: "Datos proveedor" | D8: "Datos proveedor"
A9: Empresa: | B9: Abrigos Los Andes | D9: Empresa: | E9: Blusas Sur de Chile
A10: Rut: | B10: 77.978.8769-7 | D10: Rut: | E10: 77.978.8769-7
A11: Dirección: | B11: Los Andes, Chile | D11: Dirección: | E11: Patalonía, Chile
A12: Contacto: | B12: Abrigosfrios.cl | D12: Contacto: | E12: Blusasellas.cl
A13: "Detalle de Compra" | D13: "Detalle de Compra"
A14: SKU: | B14: ABRG001-ABRG003 | D14: SKU: | E14: BLSB001
A15: PRODUCTO: | B15: Costo: | D15: PRODUCTO: | E15: Costo:
A16: Abrigo Café Mufon (10) | B16: =30000*10 -> 300000 | D16: Blusa Básica (10) | E16: =20000*10 -> 200000
A17: Abrigo Verde Lana (10) | B17: =30000*10 -> 300000 | D17: Blusa Elegante (10) | E17: =20000*10 -> 200000
A18: Abrigo Chenille (10) | B18: =30000*10 -> 300000 | D18: Blusa Casual (10) | E18: =20000*10 -> 200000
A19: CANTIDAD TOTAL: | B19: 30 | D19: CANTIDAD TOTAL: | E19: 30
A20: Total Neto: | B20: =SUM(B16:B18) -> 900000 | D20: Total Neto: | E20: =SUM(E16:E18) -> 600000
A21: IVA%: | B21: =B20*19% -> 171000 | D21: IVA%: | E21: =E20*19% -> 114000
A22: Total : | B22: =SUM(B20,B21) -> 1071000 | D22: Total : | E22: =SUM(E20,E21) -> 714000
A24: OC 003 "PANTALÓN" | D24: OC 004 "ZAPATOS"
A25: "Datos Comprador" | D25: "Datos Comprador"
A26: Empresa: | B26: Legacy SPA | D26: Empresa: | E26: Legacy SPA
A27: Rut: | B27: 77.756.968-8 | D27: Rut: | E27: 77.756.968-8
A28: Dirección: | B28: Av. Carlos Schorr, Talca | D28: Dirección: | E28: Av. Carlos Schorr, Talca
A29: Contacto: | B29: Legacy.cl | D29: Contacto: | E29: Legacy.cl
A30: Fecha: | B30: 46116 | D30: Fecha: | E30: 46116
A31: "Datos proveedor" | D31: "Datos proveedor"
A32: Empresa: | B32: Pantalones elegantes SPA | D32: Empresa: | E32: Flexi, SPA
A33: Rut: | B33: 77.978.8769-7 | D33: Rut: | E33: 77.978.8769-7
A34: Dirección: | B34: Talca, Chile | D34: Dirección: | E34: Talca, Chile
A35: Contacto: | B35: Confecciónmanual.cl | D35: Contacto: | E35: Flexiechoes.cl
A36: "Detalle de Compra" | D36: "Detalle de Compra"
A37: SKU: | B37: PT001-JNS003 | D37: SKU: | E37: PT001-JNS003
A38: PRODUCTO: | B38: Costo: | D38: PRODUCTO: | E38: Costo:
A39: Pantalón Tela (10) | B39: =40000*10 -> 400000 | D39: Zapato Romana (10) | E39: =50000*10 -> 500000
A40: Pantalón Básico (10) | B40: =40000*10 -> 400000 | D40: Botín Café Flexi (10) | E40: =50000*10 -> 500000
A41: Jeans (10) | B41: =35000*10 -> 350000 | D41: Sandalia Beige (10) | E41: =45000*10 -> 450000
...

Sheet OC VISUAL
A1: OC001 – Proveedor Abrigos
A2: SKU | B2: Producto | C2: Cant | D2: Costo Unitario | E2: Total Neto | F2: IVA $ | G2: Total
A3: ABRG001 | B3: Abrigo Café Mufon | C3: 10 | D3: 30000 | E3: 300000 | F3: 171000 | G3: 1071000
A4: ABRG002 | B4: Abrigo Verde Lana | C4: 10 | D4: 30000 | E4: 300000
A5: ABRG003 | B5: Abrigo Chenille | C5: 10 | D5: 30000 | E5: 300000
A7: OC002 – Proveedor Blusas
A8: SKU | B8: Producto | C8: Cant | D8: Costo Unitario | E8: Total Neto | F8: IVA $ | G8: Total
A9: BLSB001 | B9: Blusa Básica | C9: 10 | D9: 20000 | E9: 200000 | F9: 114000 | G9: 714000
A10: BLSE002 | B10: Blusa Elegante | C10: 10 | D10: 20000 | E10: 200000
A11: BLSC003 | B11: Blusa Casual | C11: 10 | D11: 20000 | E11: 200000
A13: OC003 – Proveedor Pantalones
A14: SKU | B14: Producto | C14: Cant | D14: Costo Unitario | E14: Total Neto | F14: IVA $ | G14: Total
A15: PT001 | B15: Pantalón Tela | C15: 10 | D15: 40000 | E15: 400000 | F15: 218500 | G15: 1368500
A16: PT002 | B16: Pantalón Básico | C16: 10 | D16: 40000 | E16: 400000
A17: JNS003 | B17: Jeans | C17: 10 | D17: 35000 | E17: 350000
A19: OC004 – Proveedor Calzado
A20: SKU | B20: Producto | C20: Cant | D20: Costo Unitario | E20: Total Neto | F20: IVA $ | G20: Total
A21: ZPT001 | B21: Zapato Romana | C21: 10 | D21: 50000 | E21: 500000 | F21: 275500 | G21: 1725500
A22: ZPT002 | B22: Botín Café Flexi | C22: 10 | D22: 50000 | E22: 500000
A23: ZPT003 | B23: Sandalia Beige | C23: 10 | D23: 45000 | E23: 450000
A26: OC005 – Proveedor Accesorios
A27: SKU | B27: Producto | C27: Cant | D27: Costo Unitario | E27: Total Neto | F27: IVA $ | G27: Total
A28: BLSL001 | B28: Bolso Legítimo | C28: 10 | D28: 30000 | E28: 300000 | F28: 294500 | G28: 1844500
A29: BLSL002 | B29: Bolso Legitimo Albacara | C29: 10 | D29: 35000 | E29: 350000
A30: CC001 | B30: Cinturón Cuero | C30: 10 | D30: 20000 | E30: 200000
A31: AU001 | B31: Aretes Oro | C31: 10 | D31: 70000 | E31: 700000
A34: TOTAL COMPRAS (Salida de caja)
A35: =SUM(G3,G9,G15,G21,G28) -> 6723500
A36: INVERSIÓN EN MERCADERÍA:
A37: 5650000
A38: IVA CF
A39: =SUM(F3,F9,F15,F21,F28) -> 1073500

Sheet Ficha de Productos
A1: SKU | B1: Nombre | C1: Categoría | D1: Talla | E1: Color | F1: Costo Neto | G1: Precio NETO (venta)
A2: ABRG001 | B2: Abrigo Café Mufon | C2: Abrigo | D2: U | E2: Café | F2: 30000 | G2: 60000
A3: ABRG002 | B3: Abrigo Verde Lana | C3: Abrigo | D3: U | E3: Verde Musgo | F3: 30000 | G3: 60000
A4: ABRG003 | B4: Abrigo Chenille | C4: Abrigo | D4: U | E4: Amarillo | F4: 30000 | G4: 60000
A5: BLSB001 | B5: Blusa Básica | C5: Blusa | D5: S | E5: Blanca | F5: 20000 | G5: 40000
A6: BLSE002 | B6: Blusa Elegante | C6: Blusa | D6: M | E6: Negra | F6: 20000 | G6: 40000
A7: BLSC003 | B7: Blusa Casual | C7: Blusa | D7: L | E7: Morada | F7: 20000 | G7: 40000
A8: PT001 | B8: Pantalón Tela | C8: Pantalón | D8: U | E8: Café | F8: 40000 | G8: 60000
A9: PT002 | B9: Pantalón Básico | C9: Pantalón | D9: U | E9: Negro | F9: 40000 | G9: 60000
A10: JNS003 | B10: Jeans | C10: Jeans | D10: U | E10: Azul | F10: 35000 | G10: 55000
A11: ZPT001 | B11: Zapato Romana | C11: Zapato | D11: 37 | E11: Café | F11: 50000 | G11: 80000
A12: ZPT002 | B12: Botín Café Flexi | C12: Zapato | D12: 37 | E12: Café | F12: 50000 | G12: 80000
A13: ZPT003 | B13: Sandalia Beige | C13: Zapato | D13: 37 | E13: Beige | F13: 45000 | G13: 70000
A14: BLSL001 | B14: Bolso Legítimo | C14: Accesorio | D14: U | E14: Diseño Negro | F14: 30000 | G14: 120000
A15: BLSL002 | B15: Bolso Legitimo Albacara | C15: Accesorio | D15: U | E15: Diseño Café | F15: 35000 | G15: 120000
A16: CC001 | B16: Cinturón Cuero | C16: Accesorio | D16: U | E16: Negro | F16: 20000 | G16: 50000
A17: AU001 | B17: Aretes Oro | C17: Accesorio | D17: U | E17: Dorado | F17: 70000 | G17: 120000

Sheet Inventario 
A1: SKU | B1: Nombre | C1: Entradas | D1: Salidas | E1: Stock | F1: Costo unitario | G1: Valor (inventario)
A2: ABRG001 | B2: Abrigo Café Mufon | C2: 10 | D2: =SUMIF(Ventas!E:E,'Inventario '!A2,Ventas!F:F) -> 2 | E2: =C2-D2 -> 8 | F2: =VLOOKUP(A2,'Ficha de Productos'!A1:G17,6,FALSE) -> 30000 | G2: =E2*F2 -> 240000
A3: ABRG002 | B3: Abrigo Verde Lana | C3: 10 | D3: =SUMIF(Ventas!E:E,'Inventario '!A3,Ventas!F:F) -> 0 | E3: =C3-D3 -> 10 | F3: =VLOOKUP(A3,'Ficha de Productos'!A2:G18,6,FALSE) -> 30000 | G3: =E3*F3 -> 300000
A4: ABRG003 | B4: Abrigo Chenille | C4: 10 | D4: =SUMIF(Ventas!E:E,'Inventario '!A4,Ventas!F:F) -> 0 | E4: =C4-D4 -> 10 | F4: =VLOOKUP(A4,'Ficha de Productos'!A3:G19,6,FALSE) -> 30000 | G4: =E4*F4 -> 300000
A5: BLSB001 | B5: Blusa Básica | C5: 10 | D5: =SUMIF(Ventas!E:E,'Inventario '!A5,Ventas!F:F) -> 3 | E5: =C5-D5 -> 7 | F5: =VLOOKUP(A5,'Ficha de Productos'!A4:G20,6,FALSE) -> 20000 | G5: =E5*F5 -> 140000
A6: BLSE002 | B6: Blusa Elegante | C6: 10 | D6: =SUMIF(Ventas!E:E,'Inventario '!A6,Ventas!F:F) -> 2 | E6: =C6-D6 -> 8 | F6: =VLOOKUP(A6,'Ficha de Productos'!A5:G21,6,FALSE) -> 20000 | G6: =E6*F6 -> 160000
A7: BLSC003 | B7: Blusa Casual | C7: 10 | D7: =SUMIF(Ventas!E:E,'Inventario '!A7,Ventas!F:F) -> 0 | E7: =C7-D7 -> 10 | F7: =VLOOKUP(A7,'Ficha de Productos'!A6:G22,6,FALSE) -> 20000 | G7: =E7*F7 -> 200000
A8: PT001 | B8: Pantalón Tela | C8: 10 | D8: =SUMIF(Ventas!E:E,'Inventario '!A8,Ventas!F:F) -> 2 | E8: =C8-D8 -> 8 | F8: =VLOOKUP(A8,'Ficha de Productos'!A7:G23,6,FALSE) -> 40000 | G8: =E8*F8 -> 320000
A9: PT002 | B9: Pantalón Básico | C9: 10 | D9: =SUMIF(Ventas!E:E,'Inventario '!A9,Ventas!F:F) -> 0 | E9: =C9-D9 -> 10 | F9: =VLOOKUP(A9,'Ficha de Productos'!A8:G24,6,FALSE) -> 40000 | G9: =E9*F9 -> 400000
A10: JNS003 | B10: Jeans | C10: 10 | D10: =SUMIF(Ventas!E:E,'Inventario '!A10,Ventas!F:F) -> 1 | E10: =C10-D10 -> 9 | F10: =VLOOKUP(A10,'Ficha de Productos'!A9:G25,6,FALSE) -> 35000 | G10: =E10*F10 -> 315000
A11: ZPT001 | B11: Zapato Romana | C11: 10 | D11: =SUMIF(Ventas!E:E,'Inventario '!A11,Ventas!F:F) -> 1 | E11: =C11-D11 -> 9 | F11: =VLOOKUP(A11,'Ficha de Productos'!A10:G26,6,FALSE) -> 50000 | G11: =E11*F11 -> 450000
A12: ZPT002 | B12: Botín Café Flexi | C12: 10 | D12: =SUMIF(Ventas!E:E,'Inventario '!A12,Ventas!F:F) -> 0 | E12: =C12-D12 -> 10 | F12: =VLOOKUP(A12,'Ficha de Productos'!A11:G27,6,FALSE) -> 50000 | G12: =E12*F12 -> 500000
A13: ZPT003 | B13: Sandalia Beige | C13: 10 | D13: =SUMIF(Ventas!E:E,'Inventario '!A13,Ventas!F:F) -> 2 | E13: =C13-D13 -> 8 | F13: =VLOOKUP(A13,'Ficha de Productos'!A12:G28,6,FALSE) -> 45000 | G13: =E13*F13 -> 360000
... A17: AU001 | B17: Aretes Oro | C17: 10 | D17: =SUMIF(Ventas!E:E,'Inventario '!A17,Ventas!F:F) -> 1 | E17: =C17-D17 -> 9 | F17: =VLOOKUP(A17,'Ficha de Productos'!A16:G32,6,FALSE) -> 70000 | G17: =E17*F17 -> 630000
G18: Valor total inventario
A19: "BUSCADOR" | G19: =SUM(G2:G17) -> 5095000
A20: INGRESAR SKU -> | C20: ABRG001
A21: Detalle del producto: | C21: =VLOOKUP(C20,A1:G17,2,FALSE) -> Abrigo Café Mufon
A22: Stock disponible: | C22: =VLOOKUP(C20,A1:G17,5) -> 8

Sheet Clientes
A1: ID_Cliente | B1: Nombre | C1: Rut | D1: Comuna | E1: Email | F1: Fecha de Compra
A2: CL001 | B2: María Pérez | C2: 12.345.678-9 | D2: Santiago | E2: maria.perez@mail.cl | F2: 46118
A3: CL002 | B3: Juan Soto | C3: 13.456.789-0 | D3: Providencia | E3: juan.soto@mail.cl | F3: 46118
A4: CL003 | B4: Ana Rojas | C4: 14.567.890-1 | D4: Ñuñoa | E4: ana.rojas@mail.cl | F4: 46119
A5: CL004 | B5: Pedro Díaz | C5: 15.678.901-2 | D5: Maipú | E5: pedro.diaz@mail.cl | F5: 46121
A6: CL005 | B6: Sofía León | C6: 16.789.012-3 | D6: La Florida | E6: sofia.leon@mail.cl | F6: 46124

Sheet Ventas
A1: ID VENTA | B1: Fecha | C1: ID Cliente | D1: Producto | E1: SKU | F1: Cantidad | G1: Precio Unitario | H1: Neto | I1: IVA DF | J1: Total
A2: V001 | B2: 46118 | C2: CL001 | D2: Abrigo Café Mufon | E2: ABRG001 | F2: 2 | G2: 60000 | H2: =G2*F2 -> 120000 | I2: =H2*19% -> 22800 | J2: =SUM(H2,I2) -> 142800
A3: V001 | B3: 46118 | C3: CL001 | D3: Blusa Básica | E3: BLSB001 | F3: 3 | G3: 40000 | H3: =G3*F3 -> 120000 | I3: =H3*19% -> 22800 | J3: =SUM(H3,I3) -> 142800
A4: V002 | B4: 46118 | C4: CL002 | D4: Pantalón Tela | E4: PT001 | F4: 2 | G4: 60000 | H4: =G4*F4 -> 120000 | I4: =H4*19% -> 22800 | J4: =SUM(H4,I4) -> 142800
A5: V002 | B5: 46118 | C5: CL002 | D5: Jeans | E5: JNS003 | F5: 1 | G5: 55000 | H5: =G5*F5 -> 55000 | I5: =H5*19% -> 10450 | J5: =SUM(H5,I5) -> 65450
A6: V003 | B6: 46119 | C6: CL003 | D6: Zapato Romana | E6: ZPT001 | F6: 1 | G6: 80000 | H6: =G6*F6 -> 80000 | I6: =H6*19% -> 15200 | J6: =SUM(H6,I6) -> 95200
A7: V003 | B7: 46119 | C7: CL003 | D7: Sandalia Beige | E7: ZPT003 | F7: 2 | G7: 70000 | H7: =G7*F7 -> 140000 | I7: =H7*19% -> 26600 | J7: =SUM(H7,I7) -> 166600
A8: V004 | B8: 46121 | C8: CL004 | D8: Bolso Legítimo | E8: BLSL001 | F8: 1 | G8: 120000 | H8: =G8*F8 -> 120000 | I8: =H8*19% -> 22800 | J8: =SUM(H8,I8) -> 142800
A9: V004 | B9: 46121 | C9: CL004 | D9: Cinturón Cuero | E9: CC001 | F9: 2 | G9: 50000 | H9: =G9*F9 -> 100000 | I9: =H9*19% -> 19000 | J9: =SUM(H9,I9) -> 119000
A10: V005 | B10: 46124 | C10: CL005 | D10: Aretes Oro | E10: AU001 | F10: 1 | G10: 120000 | H10: =G10*F10 -> 120000 | I10: =H10*19% -> 22800 | J10: =SUM(H10,I10) -> 142800
A11: V005 | B11: 46124 | C11: CL005 | D11: Blusa Elegante | E11: BLSE002 | F11: 2 | G11: 40000 | H11: =G11*F11 -> 80000 | I11: =H11*19% -> 15200 | J11: =SUM(H11,I11) -> 95200
H12: TOTAL NETO | I12: TOTAL DF | J12: Total Venta
H13: =SUM(H2:H11) -> 1055000 | I13: =SUM(I2:I11) -> 200450 | J13: =SUM(J2:J11) -> 1255450

Sheet Factura de Venta
A1: DOCUMENTO DE VENTA N°001
A2: Datos del Cliente
A3: ID Venta | B3: V001 | D3: Nombre | E3: =VLOOKUP(B5,Clientes!A1:F6,2,FALSE) -> María Pérez
A4: Fecha: | B4: =VLOOKUP(B3,Ventas!A1:J11,2,FALSE) -> 46118 | D4: RUT: | E4: =VLOOKUP(B5,Clientes!A2:F7,3,FALSE) -> 12.345.678-9
A5: ID Cliente | B5: =VLOOKUP(B3,Ventas!A1:J11,3,FALSE) -> CL001 | D5: Comuna: | E5: =VLOOKUP(B5,Clientes!A1:F6,4,FALSE) -> Santiago
A6: Forma de pago | B6: Transferencia | D6: Email: | E6: =VLOOKUP(B5,Clientes!A2:F7,5,FALSE) -> maria.perez@mail.cl
A7: Detalle de Venta
A8: SKU | B8: Producto | C8: Cantidad | D8: Precio Unitario | E8: Neto | F8: IVA DF | G8: Total
A9: ABRG001 | B9: Abrigo Café Mufon | C9: 2 | D9: 60000 | E9: =D9*C9 -> 120000 | F9: =E9*19% -> 22800 | G9: =SUM(E9,F9) -> 142800
A10: BLSB001 | B10: Blusa Básica | C10: 3 | D10: 40000 | E10: =D10*C10 -> 120000 | F10: =E10*19% -> 22800 | G10: =SUM(E10,F10) -> 142800
A12: TOTAL NETO | B12: =SUM(E9:E10) -> 240000 | E12: OBSERVACIONES:
A13: TOTAL IVA | B13: =SUM(F9:F10) -> 45600 | E13: Entrega normal
A14: TOTAL ORDEN | B14: =SUM(B12:B13) -> 285600
A16: DOCUMENTO DE VENTA N°002
A17: Datos del Cliente
A18: ID Venta | B18: V002 | D18: Nombre | E18: =VLOOKUP(B$20,Clientes!A1:F6,2,FALSE) -> Juan Soto
A19: Fecha: | B19: 46118 | D19: RUT: | E19: =VLOOKUP(B$20,Clientes!A2:F7,3,FALSE) -> 13.456.789-0
A20: ID Cliente | B20: CL002 | D20: Comuna: | E20: =VLOOKUP(B$20,Clientes!A3:F8,4,FALSE) -> Providencia
A21: Forma de pago | B21: Transferencia | D21: Email: | E21: =VLOOKUP(B20,Clientes!A1:F6,5,FALSE) -> juan.soto@mail.cl
A22: Detalle de Venta
A23: Producto | B23: SKU | C23: Cantidad | D23: Precio Unitario | E23: Neto | F23: IVA DF | G23: Total
A24: Pantalón Tela | B24: PT001 | C24: 2 | D24: 60000 | E24: =D24*C24 -> 120000 | F24: =E24*19% -> 22800 | G24: =SUM(E24,F24) -> 142800
A25: Jeans | B25: JNS003 | C25: 1 | D25: 55000 | E25: =D25*C25 -> 55000 | F25: =E25*19% -> 10450 | G25: =SUM(E25,F25) -> 65450
A27: TOTAL NETO | B27: =SUM(E24:E25) -> 175000 | E27: OBSERVACIONES:
A28: TOTAL IVA | B28: =SUM(F24:F25) -> 33250 | E28: Entrega normal
A29: TOTAL ORDEN | B29: =SUM(B27:B28) -> 208250
A31: DOCUMENTO DE VENTA N°003
A32: Datos del Cliente
A33: ID Venta | B33: V003 | D33: Nombre | E33: =VLOOKUP(B$35,Clientes!A1:F6,2,FALSE) -> Ana Rojas
A34: Fecha: | B34: 46119 | D34: RUT: | E34: =VLOOKUP(B$35,Clientes!A2:F7,3,FALSE) -> 14.567.890-1
A35: ID Cliente | B35: CL003 | D35: Comuna: | E35: =VLOOKUP(B$35,Clientes!A3:F8,4,FALSE) -> Ñuñoa
A36: Forma de pago | B36: Transferencia | D36: Email: | E36: =VLOOKUP(B$35,Clientes!A4:F9,5,FALSE) -> ana.rojas@mail.cl
A37: Detalle de Venta
A38: Producto | B38: SKU | C38: Cantidad | D38: Precio Unitario | E38: Neto | F38: IVA DF | G38: Total
A39: Zapato Romana | B39: ZPT001 | C39: 1 | D39: 80000 | E39: =D39*C39 -> 80000 | F39: =E39*19% -> 15200 | G39: =SUM(E39,F39) -> 95200
A40: Sandalia Beige | B40: ZPT003 | C40: 2 | D40: 70000 | E40: =D40*C40 -> 140000 | F40: =E40*19% -> 26600 | G40: =SUM(E40,F40) -> 166600
A42: TOTAL NETO | B42: =SUM(E39:E40) -> 220000 | E42: OBSERVACIONES:
A43: TOTAL IVA | B43: =SUM(F39:F40) -> 41800 | E43: Entrega normal
A44: TOTAL ORDEN | B44: =SUM(B42:B43) -> 261800
A46: DOCUMENTO DE VENTA N°004
...

Sheet Costos
A1: SKU | B1: Producto | C1: Cantidad Vendida | D1: Costo Unitario | E1: Costo Total
A2: ABRG001 | B2: Abrigo Café Mufon | C2: 2 | D2: =VLOOKUP(A2,'Ficha de Productos'!A1:G17,6,FALSE) -> 30000 | E2: =D2*C2 -> 60000
A3: BLSB001 | B3: Blusa Básica | C3: 3 | D3: =VLOOKUP(A3,'Ficha de Productos'!A2:G18,6,FALSE) -> 20000 | E3: =D3*C3 -> 60000
A4: PT001 | B4: Pantalón Tela | C4: 2 | D4: =VLOOKUP(A4,'Ficha de Productos'!A3:G19,6,FALSE) -> 40000 | E4: =D4*C4 -> 80000
A5: JNS003 | B5: Jeans | C5: 1 | D5: =VLOOKUP(A5,'Ficha de Productos'!A4:G20,6,FALSE) -> 35000 | E5: =D5*C5 -> 35000
A6: ZPT001 | B6: Zapato Romana | C6: 1 | D6: =VLOOKUP(A6,'Ficha de Productos'!A5:G21,6,FALSE) -> 50000 | E6: =D6*C6 -> 50000
A7: ZPT003 | B7: Sandalia Beige | C7: 2 | D7: =VLOOKUP(A7,'Ficha de Productos'!A6:G22,6,FALSE) -> 45000 | E7: =D7*C7 -> 90000
A8: BLSL001 | B8: Bolso Legítimo | C8: 1 | D8: =VLOOKUP(A8,'Ficha de Productos'!A7:G23,6,FALSE) -> 30000 | E8: =D8*C8 -> 30000
A9: CC001 | B9: Cinturón Cuero | C9: 2 | D9: =VLOOKUP(A9,'Ficha de Productos'!A8:G24,6,FALSE) -> 20000 | E9: =D9*C9 -> 40000
A10: AU001 | B10: Aretes Oro | C10: 1 | D10: =VLOOKUP(A10,'Ficha de Productos'!A9:G25,6,FALSE) -> 70000 | E10: =D10*C10 -> 70000
A11: BLSE002 | B11: Blusa Elegante | C11: 2 | D11: =VLOOKUP(A11,'Ficha de Productos'!A1:G17,6,FALSE) -> 20000 | E11: =D11*C11 -> 40000
E12: Total de costos
E13: =SUM(E2:E11) -> 555000

Sheet No Inventariable
A1: Fecha | B1: Categoría | C1: Subcategoría | D1: Descripción | E1: NETO | F1: IVA Crédito | G1: TOTAL | H1: Medio de Pago | I1: Tipo Documento | J1: N°Doc
A2: 46113 | B2: Gasto Operacional | C2: Arriendo | D2: Local boutique | E2: =G2-F2 -> 300000 | F2: 0 | G2: 300000 | H2: Transferencia | I2: Factura | J2: 1001
A3: 46114 | B3: Gasto de Venta | C3: Marketing Digital | D3: Publicidad | E3: =G3-F3 -> 40500 | F3: =G3*19% -> 9500 | G3: 50000 | H3: Tarjeta | I3: Factura | J3: 2050
A4: 46115 | B4: Gasto Operacional | C4: Logística | D4: Envíos pedidos | E4: =G4-F4 -> 24300 | F4: =G4*19% -> 5700 | G4: 30000 | H4: Efectivo | I4: Factura | J4: 3321

Sheet Analisis de productos
A1: SKU | B1: Producto | C1: Categoría | D1: Ventas | E1: Ingresos (neto) | F1: Costo total | G1: Utilidad | H1: Margen | I1: IVA DF | J1: Total Ventas | K1: Rotación | L1: ESTADO
A2: ABRG001 | B2: Abrigo Café Mufon | C2: Abrigo | D2: =IFERROR(SUMIF(Ventas!E:E,'Analisis de productos'!A2,Ventas!F:F),0) -> 2 | E2: =D2*(VLOOKUP(A2,'Ficha de Productos'!A:G,7,FALSE)) -> 120000 | F2: =IFERROR(D2*VLOOKUP(A2,'Ficha de Productos'!A:G,6,FALSE),0) -> 60000 | G2: =E2-F2 -> 60000 | H2: =IFERROR(G2/E2,0) -> 0.5 | I2: =IFERROR(E2*19%,0) -> 22800 | J2: =IFERROR(E2+I2,0) -> 142800 | K2: =IFERROR(D2/VLOOKUP(A2,'Inventario '!A:E,5,FALSE),0) -> 0.25 | L2: =IF(D2=0,"Sin Ventas",IF(AND(H2>0.5,D2>=2),"Estrella",IF(D2=1,"Baja Rotación",IF(H2<0.4,"Bajo Margen","Normal")))) -> Normal
A3: ABRG002 | B3: Abrigo Verde Lana | C3: Abrigo | D3: =IFERROR(SUMIF(Ventas!E:E,'Analisis de productos'!A3,Ventas!F:F),0) -> 0 | E3: =D3*(VLOOKUP(A3,'Ficha de Productos'!A:G,7,FALSE)) -> 0 | F3: =IFERROR(D3*VLOOKUP(A3,'Ficha de Productos'!A:G,6,FALSE),0) -> 0 | G3: =E3-F3 -> 0 | H3: =IFERROR(G3/E3,0) -> 0 | I3: =IFERROR(E3*19%,0) -> 0 | J3: =IFERROR(E3+I3,0) -> 0 | K3: =IFERROR(D3/VLOOKUP(A3,'Inventario '!A:E,5,FALSE),0) -> 0 | L3: =IF(D3=0,"Sin Ventas",IF(AND(H3>0.5,D3>=2),"Estrella",IF(D3=1,"Baja Rotación",IF(H3<0.4,"Bajo Margen","Normal")))) -> Sin Ventas
A4: ABRG003 | B4: Abrigo Chenille | C4: Abrigo | D4: =IFERROR(SUMIF(Ventas!E:E,'Analisis de productos'!A4,Ventas!F:F),0) -> 0 | E4: =D4*(VLOOKUP(A4,'Ficha de Productos'!A:G,7,FALSE)) -> 0 | F4: =IFERROR(D4*VLOOKUP(A4,'Ficha de Productos'!A:G,6,FALSE),0) -> 0 | G4: =E4-F4 -> 0 | H4: =IFERROR(G4/E4,0) -> 0 | I4: =IFERROR(E4*19%,0) -> 0 | J4: =IFERROR(E4+I4,0) -> 0 | K4: =IFERROR(D4/VLOOKUP(A4,'Inventario '!A:E,5,FALSE),0) -> 0 | L4: =IF(D4=0,"Sin Ventas",IF(AND(H4>0.5,D4>=2),"Estrella",IF(D4=1,"Baja Rotación",IF(H4<0.4,"Bajo Margen","Normal")))) -> Sin Ventas
A5: BLSB001 | B5: Blusa Básica | C5: Blusa | D5: =IFERROR(SUMIF(Ventas!E:E,'Analisis de productos'!A5,Ventas!F:F),0) -> 3 | E5: =D5*(VLOOKUP(A5,'Ficha de Productos'!A:G,7,FALSE)) -> 120000 | F5: =IFERROR(D5*VLOOKUP(A5,'Ficha de Productos'!A:G,6,FALSE),0) -> 60000 | G5: =E5-F5 -> 60000 | H5: =IFERROR(G5/E5,0) -> 0.5 | I5: =IFERROR(E5*19%,0) -> 22800 | J5: =IFERROR(E5+I5,0) -> 142800 | K5: =IFERROR(D5/VLOOKUP(A5,'Inventario '!A:E,5,FALSE),0) -> 0.42857143 | L5: =IF(D5=0,"Sin Ventas",IF(AND(H5>0.5,D5>=2),"Estrella",IF(D5=1,"Baja Rotación",IF(H5<0.4,"Bajo Margen","Normal")))) -> Normal
A6: BLSE002 | B6: Blusa Elegante | C6: Blusa | D6: =IFERROR(SUMIF(Ventas!E:E,'Analisis de productos'!A6,Ventas!F:F),0) -> 2 | E6: =D6*(VLOOKUP(A6,'Ficha de Productos'!A:G,7,FALSE)) -> 80000 | F6: =IFERROR(D6*VLOOKUP(A6,'Ficha de Productos'!A:G,6,FALSE),0) -> 40000 | G6: =E6-F6 -> 40000 | H6: =IFERROR(G6/E6,0) -> 0.5 | I6: =IFERROR(E6*19%,0) -> 15200 | J6: =IFERROR(E6+I6,0) -> 95200 | K6: =IFERROR(D6/VLOOKUP(A6,'Inventario '!A:E,5,FALSE),0) -> 0.25 | L6: =IF(D6=0,"Sin Ventas",IF(AND(H6>0.5,D6>=2),"Estrella",IF(D6=1,"Baja Rotación",IF(H6<0.4,"Bajo Margen","Normal")))) -> Normal
A7: BLSC003 | B7: Blusa Casual | C7: Blusa | D7: =IFERROR(SUMIF(Ventas!E:E,'Analisis de productos'!A7,Ventas!F:F),0) -> 0 | E7: =D7*(VLOOKUP(A7,'Ficha de Productos'!A:G,7,FALSE)) -> 0 | F7: =IFERROR(D7*VLOOKUP(A7,'Ficha de Productos'!A:G,6,FALSE),0) -> 0 | G7: =E7-F7 -> 0 | H7: =IFERROR(G7/E7,0) -> 0 | I7: =IFERROR(E7*19%,0) -> 0 | J7: =IFERROR(E7+I7,0) -> 0 | K7: =IFERROR(D7/VLOOKUP(A7,'Inventario '!A:E,5,FALSE),0) -> 0 | L7: =IF(D7=0,"Sin Ventas",IF(AND(H7>0.5,D7>=2),"Estrella",IF(D7=1,"Baja Rotación",IF(H7<0.4,"Bajo Margen","Normal")))) -> Sin Ventas
A8: PT001 | B8: Pantalón Tela | C8: Pantalón | D8: =IFERROR(SUMIF(Ventas!E:E,'Analisis de productos'!A8,Ventas!F:F),0) -> 2 | E8: =D8*(VLOOKUP(A8,'Ficha de Productos'!A:G,7,FALSE)) -> 120000 | F8: =IFERROR(D8*VLOOKUP(A8,'Ficha de Productos'!A:G,6,FALSE),0) -> 80000 | G8: =E8-F8 -> 40000 | H8: =IFERROR(G8/E8,0) -> 0.33333333 | I8: =IFERROR(E8*19%,0) -> 22800 | J8: =IFERROR(E8+I8,0) -> 142800 | K8: =IFERROR(D8/VLOOKUP(A8,'Inventario '!A:E,5,FALSE),0) -> 0.25 | L8: =IF(D8=0,"Sin Ventas",IF(AND(H8>0.5,D8>=2),"Estrella",IF(D8=1,"Baja Rotación",IF(H8<0.4,"Bajo Margen","Normal")))) -> Bajo Margen
A9: PT002 | B9: Pantalón Básico | C9: Pantalón | D9: =IFERROR(SUMIF(Ventas!E:E,'Analisis de productos'!A9,Ventas!F:F),0) -> 0 | E9: =D9*(VLOOKUP(A9,'Ficha de Productos'!A:G,7,FALSE)) -> 0 | F9: =IFERROR(D9*VLOOKUP(A9,'Ficha de Productos'!A:G,6,FALSE),0) -> 0 | G9: =E9-F9 -> 0 | H9: =IFERROR(G9/E9,0) -> 0 | I9: =IFERROR(E9*19%,0) -> 0 | J9: =IFERROR(E9+I9,0) -> 0 | K9: =IFERROR(D9/VLOOKUP(A9,'Inventario '!A:E,5,FALSE),0) -> 0 | L9: =IF(D9=0,"Sin Ventas",IF(AND(H9>0.5,D9>=2),"Estrella",IF(D9=1,"Baja Rotación",IF(H9<0.4,"Bajo Margen","Normal")))) -> Sin Ventas
A10: JNS003 | B10: Jeans | C10: Jeans | D10: =IFERROR(SUMIF(Ventas!E:E,'Analisis de productos'!A10,Ventas!F:F),0) -> 1 | E10: =D10*(VLOOKUP(A10,'Ficha de Productos'!A:G,7,FALSE)) -> 55000 | F10: =IFERROR(D10*VLOOKUP(A10,'Ficha de Productos'!A:G,6,FALSE),0) -> 35000 | G10: =E10-F10 -> 20000 | H10: =IFERROR(G10/E10,0) -> 0.36363636 | I10: =IFERROR(E10*19%,0) -> 10450 | J10: =IFERROR(E10+I10,0) -> 65450 | K10: =IFERROR(D10/VLOOKUP(A10,'Inventario '!A:E,5,FALSE),0) -> 0.11111111 | L10: =IF(D10=0,"Sin Ventas",IF(AND(H10>0.5,D10>=2),"Estrella",IF(D10=1,"Baja Rotación",IF(H10<0.4,"Bajo Margen","Normal")))) -> Baja Rotación
A11: ZPT001 | B11: Zapato Romana | C11: Zapato | D11: =IFERROR(SUMIF(Ventas!E:E,'Analisis de productos'!A11,Ventas!F:F),0) -> 1 | E11: =D11*(VLOOKUP(A11,'Ficha de Productos'!A:G,7,FALSE)) -> 80000 | F11: =IFERROR(D11*VLOOKUP(A11,'Ficha de Productos'!A:G,6,FALSE),0) -> 50000 | G11: =E11-F11 -> 30000 | H11: =IFERROR(G11/E11,0) -> 0.375 | I11: =IFERROR(E11*19%,0) -> 15200 | J11: =IFERROR(E11+I11,0) -> 95200 | K11: =IFERROR(D11/VLOOKUP(A11,'Inventario '!A:E,5,FALSE),0) -> 0.11111111 | L11: =IF(D11=0,"Sin Ventas",IF(AND(H11>0.5,D11>=2),"Estrella",IF(D11=1,"Baja Rotación",IF(H11<0.4,"Bajo Margen","Normal")))) -> Baja Rotación
A12: ZPT002 | B12: Botín Café Flexi | C12: Zapato | D12: =IFERROR(SUMIF(Ventas!E:E,'Analisis de productos'!A12,Ventas!F:F),0) -> 0 | E12: =D12*(VLOOKUP(A12,'Ficha de Productos'!A:G,7,FALSE)) -> 0 | F12: =IFERROR(D12*VLOOKUP(A12,'Ficha de Productos'!A:G,6,FALSE),0) -> 0 | G12: =E12-F12 -> 0 | H12: =IFERROR(G12/E12,0) -> 0 | I12: =IFERROR(E12*19%,0) -> 0 | J12: =IFERROR(E12+I12,0) -> 0 | K12: =IFERROR(D12/VLOOKUP(A12,'Inventario '!A:E,5,FALSE),0) -> 0 | L12: =IF(D12=0,"Sin Ventas",IF(AND(H12>0.5,D12>=2),"Estrella",IF(D12=1,"Baja Rotación",IF(H12<0.4,"Bajo Margen","Normal")))) -> Sin Ventas
A13: ZPT003 | B13: Sandalia Beige | C13: Zapato | D13: =IFERROR(SUMIF(Ventas!E:E,'Analisis de productos'!A13,Ventas!F:F),0) -> 2 | E13: =D13*(VLOOKUP(A13,'Ficha de Productos'!A:G,7,FALSE)) -> 140000 | F13: =IFERROR(D13*VLOOKUP(A13,'Ficha de Productos'!A:G,6,FALSE),0) -> 90000 | G13: =E13-F13 -> 50000 | H13: =IFERROR(G13/E13,0) -> 0.35714286 | I13: =IFERROR(E13*19%,0) -> 26600 | J13: =IFERROR(E13+I13,0) -> 166600 | K13: =IFERROR(D13/VLOOKUP(A13,'Inventario '!A:E,5,FALSE),0) -> 0.25 | L13: =IF(D13=0,"Sin Ventas",IF(AND(H13>0.5,D13>=2),"Estrella",IF(D13=1,"Baja Rotación",IF(H13<0.4,"Bajo Margen","Normal")))) -> Bajo Margen
... A17: AU001 | B17: Aretes Oro | C17: Accesorio | D17: =IFERROR(SUMIF(Ventas!E:E,'Analisis de productos'!A17,Ventas!F:F),0) -> 1 | E17: =D17*(VLOOKUP(A17,'Ficha de Productos'!A:G,7,FALSE)) -> 120000 | F17: =IFERROR(D17*VLOOKUP(A17,'Ficha de Productos'!A:G,6,FALSE),0) -> 70000 | G17: =E17-F17 -> 50000 | H17: =IFERROR(G17/E17,0) -> 0.41666667 | I17: =IFERROR(E17*19%,0) -> 22800 | J17: =IFERROR(E17+I17,0) -> 142800 | K17: =IFERROR(D17/VLOOKUP(A17,'Inventario '!A:E,5,FALSE),0) -> 0.11111111 | L17: =IF(D17=0,"Sin Ventas",IF(AND(H17>0.5,D17>=2),"Estrella",IF(D17=1,"Baja Rotación",IF(H17<0.4,"Bajo Margen","Normal")))) -> Baja Rotación

Sheet Financiero 
A1: Estado de Resultados - Análisis Financiero del Sistema de Gestión | B1: Columna1
A2: Período: Abril 2026
A3: Concepto | B3: Monto
A4: Ingresos por ventas | B4: =SUM('Analisis de productos'!E:E) -> 1055000
A5: (-) Costo de Ventas | B5: =SUM('Analisis de productos'!F:F) -> 555000
A7: Utilidad Bruta | B7: =B4-B5 -> 500000
A8: (-) Gastos | B8: =SUM('No Inventariable'!E2:E4) -> 364800
A10: Utilidad Neta | B10: =B7-B8 -> 135200
A12: Margen Total | B12: =B10/B4 -> 0.12815166
A15: “Esto indica que el negocio es rentable, aunque con un margen reducido, lo que evidencia la necesidad de optimizar la gestión de costos y gastos para fortalecer la rentabilidad y asegurar un desempeño financiero más sostenible en el tiempo.”

Sheet Control IVA
A1: "Determinación de IVA" | B1: Columna1
A2: Período: Abril 2026
A3: Concepto | B3: Monto
A4: IVA Débito Fiscal | B4: =SUM('Analisis de productos'!I:I) -> 200450
A5: IVA Crédito Fiscal | B5: =SUM(1073500,'No Inventariable'!F3:F4) -> 1088700
A7: IVA a Favor | B7: =B4-B5 -> -888250
A11: Este resultado refleja que el volumen de compras y gastos afectos a IVA supera las ventas del período, evidenciando una estructura de costos y gastos significativa en relación con los ingresos generados.

Sheet Visualización de Datos
A1: Producto | B1: Suma de Utilidad
A2: Abrigo Café Mufon | B2: 60000
A3: Abrigo Chenille | B3: 0
A4: Abrigo Verde Lana | B4: 0
A5: Total general | B5: 60000
A21: Categoría | B21: Suma de Ventas
A22: Abrigo | B22: 2
A23: Total general | B23: 2
A30: Relación de ventas y utilidad por categoría
A37: VENTAS TOTALES | C37: UTILIDAD | F37: MARGEN | I37: SIN VENTAS
A38: =SUM('Analisis de productos'!E:E) -> 1055000 | C38: =SUM('Analisis de productos'!G:G) -> 500000 | F38: ='Financiero '!B10/'Financiero '!B4 -> 0.12815166 | I38: =COUNTIF('Analisis de productos'!D:D,0) -> 6
